<?xml version='1.0'?>
<robot name='proj1robot'>
  <!-- Give the robot a color -->
  <material name="robotcolor">
    <color rgba="1 0.757 0.147 1"/>
  </material>

  <!-- The main base of the robot -->
  <link name='base_link'>
    <visual>
      <geometry>
        <box size="0.2 0.4 0.2"/>
      </geometry>
      <material name="robotcolor"/>
      <origin xyz="0 0.2 0.1"/>
    </visual>
    <visual>
      <geometry>
        <box size="0.1 0.4 0.1"/>
      </geometry>
      <material name="robotcolor"/>
      <origin xyz="0 0.2 0.15"/>
    </visual>
  </link>
  
  <!-- The rear slider -->
  <link name='rear_slider'>
    <visual>
      <geometry>
        <box size="0.2 0.1 0.2"/>
      </geometry>
      <material name="robotcolor"/>
    </visual>
  </link>
  <joint name="base_rear_slider" type="fixed">
    <parent link="base_link"/>
    <child link="rear_slider"/>
    <origin xyz="0 0.05 0.1"/>
  </joint>

  <!-- The front slider -->
  <link name='front_slider'>
    <visual>
      <geometry>
        <box size="0.2 0.1 0.2"/>
      </geometry>
      <material name="robotcolor"/>
    </visual>
  </link>
  <joint name="base_front_slider" type="fixed">
    <parent link="base_link"/>
    <child link="front_slider"/>
    <origin xyz="0 0.35 0.1"/>
  </joint>

  <!-- The left wheel -->
  <link name="left_wheel">
    <visual>
      <geometry>
        <cylinder radius="0.1" length="0.05"/>
      </geometry>
      <origin xyz="0 0 -0.025"/>
    </visual>
  </link>
  <joint name="base_left_wheel" type="continuous">
    <parent link="base_link"/>
    <child link="left_wheel"/>
    <origin rpy="0 1.5708 0" xyz="-0.05 0.2 0.1"/>
  </joint>

  <!-- The right wheel -->
  <link name="right_wheel">
    <visual>
      <geometry>
        <cylinder radius="0.1" length="0.05"/>
      </geometry>
      <origin xyz="0 0 0.025"/>
    </visual>
  </link>
  <joint name="base_right_wheel" type="continuous">
    <parent link="base_link"/>
    <child link="right_wheel"/>
    <origin rpy="0 1.5708 0" xyz="0.05 0.2 0.1"/>
  </joint>

</robot>
